Workbook

Sheet Cotton Tape and Sliver
A3: Описание артикул | B3: Желано количество | C3: Поръчано Количество | D3: Желана дата за доставка | E3: Машина | F3: COM No. | G3: Submission (UTC) | I3: ID Запитване | J3: Доставчик | K3: Очаквана дата на доставка | L3: Товарителница | M3: Реална доставка | N3: Доставено количество | O3: Цена за 1 бр. в BGN | P3: Сума на поръчката в BGN | Q3: Фактура? | R3: Транспортни документи | S3: Requester Name | T3: Requester email
A4: конусна втулка H317 | B4: 6 | D4: 45827 | E4: Лента | G4: 45807.57 | H4: Доставено | I4: CT-0021 | J4: PROXTEAM | P4: =Table1[[#This Row],[Цена за 1 бр. в BGN]]*Table1[[#This Row],[Поръчано Количество]] -> 0 | S4: {=_xlfn.SWITCH(T4, "ivelikov@septona-bg.com", "Ivan Velikov", "andy@skuytov.eu", "Andrean Angelov", "ialeksandrov@septona-bg.com", "Ivailo Aleksandrov", "bgeorgiev@septona-bg.com", "Boris Georgiev", "iilev@septona-bg.com", "Ivailo Iliev", "dmitev@septona-bg.com", "Dimitar Mitev", "gkanchev@septona-bgc.com", "Georgi Kanchev", "s.kuytov@skuytov.eu", "Salim Kuytov", "istoyanova@septona-bg.com", "Ivelina Stoyanova", "ddimitrova@septona-bg.com", "Doroteya Dimitrova", "smehandzhieva@septona-bg.com", "Stiliana Mehandzhieva", "Unknown" )} -> Unknown
A5: лагер 22217KEJW33 | B5: 6 | D5: 45827 | E5: Лента | G5: 45807.57 | H5: Доставено | I5: CT-0021 | J5: PROXTEAM | P5: =Table1[[#This Row],[Цена за 1 бр. в BGN]]*Table1[[#This Row],[Поръчано Количество]] -> 0 | S5: {=_xlfn.SWITCH(T5, "ivelikov@septona-bg.com", "Ivan Velikov", "andy@skuytov.eu", "Andrean Angelov", "ialeksandrov@septona-bg.com", "Ivailo Aleksandrov", "bgeorgiev@septona-bg.com", "Boris Georgiev", "iilev@septona-bg.com", "Ivailo Iliev", "dmitev@septona-bg.com", "Dimitar Mitev", "gkanchev@septona-bgc.com", "Georgi Kanchev", "s.kuytov@skuytov.eu", "Salim Kuytov", "istoyanova@septona-bg.com", "Ivelina Stoyanova", "ddimitrova@septona-bg.com", "Doroteya Dimitrova", "smehandzhieva@septona-bg.com", "Stiliana Mehandzhieva", "Unknown" )} -> Unknown
A6: SNR/FR150x12,5x5 | B6: 12 | D6: 45827 | E6: Лента | G6: 45807.571 | H6: Доставено | I6: CT-0021 | J6: PROXTEAM | P6: =Table1[[#This Row],[Цена за 1 бр. в BGN]]*Table1[[#This Row],[Поръчано Количество]] -> 0 | S6: {=_xlfn.SWITCH(T6, "ivelikov@septona-bg.com", "Ivan Velikov", "andy@skuytov.eu", "Andrean Angelov", "ialeksandrov@septona-bg.com", "Ivailo Aleksandrov", "bgeorgiev@septona-bg.com", "Boris Georgiev", "iilev@septona-bg.com", "Ivailo Iliev", "dmitev@septona-bg.com", "Dimitar Mitev", "gkanchev@septona-bgc.com", "Georgi Kanchev", "s.kuytov@skuytov.eu", "Salim Kuytov", "istoyanova@septona-bg.com", "Ivelina Stoyanova", "ddimitrova@septona-bg.com", "Doroteya Dimitrova", "smehandzhieva@septona-bg.com", "Stiliana Mehandzhieva", "Unknown" )} -> Unknown
A7: лагерна черупка SNR/SNC.517 | B7: 6 | D7: 45827 | E7: Лента | G7: 45807.571 | H7: Доставено | I7: CT-0021 | J7: PROXTEAM | P7: =Table1[[#This Row],[Цена за 1 бр. в BGN]]*Table1[[#This Row],[Поръчано Количество]] -> 0 | S7: {=_xlfn.SWITCH(T7, "ivelikov@septona-bg.com", "Ivan Velikov", "andy@skuytov.eu", "Andrean Angelov", "ialeksandrov@septona-bg.com", "Ivailo Aleksandrov", "bgeorgiev@septona-bg.com", "Boris Georgiev", "iilev@septona-bg.com", "Ivailo Iliev", "dmitev@septona-bg.com", "Dimitar Mitev", "gkanchev@septona-bgc.com", "Georgi Kanchev", "s.kuytov@skuytov.eu", "Salim Kuytov", "istoyanova@septona-bg.com", "Ivelina Stoyanova", "ddimitrova@septona-bg.com", "Doroteya Dimitrova", "smehandzhieva@septona-bg.com", "Stiliana Mehandzhieva", "Unknown" )} -> Unknown
A8: верига 08В-1 - 5м | B8: 4 | D8: 45827 | E8: Лента | G8: 45808.182 | H8: Доставено | I8: CT-0021 | J8: PROXTEAM | P8: =Table1[[#This Row],[Цена за 1 бр. в BGN]]*Table1[[#This Row],[Поръчано Количество]] -> 0 | S8: {=_xlfn.SWITCH(T8, "ivelikov@septona-bg.com", "Ivan Velikov", "andy@skuytov.eu", "Andrean Angelov", "ialeksandrov@septona-bg.com", "Ivailo Aleksandrov", "bgeorgiev@septona-bg.com", "Boris Georgiev", "iilev@septona-bg.com", "Ivailo Iliev", "dmitev@septona-bg.com", "Dimitar Mitev", "gkanchev@septona-bgc.com", "Georgi Kanchev", "s.kuytov@skuytov.eu", "Salim Kuytov", "istoyanova@septona-bg.com", "Ivelina Stoyanova", "ddimitrova@septona-bg.com", "Doroteya Dimitrova", "smehandzhieva@septona-bg.com", "Stiliana Mehandzhieva", "Unknown" )} -> Unknown
A9: мотор siemens 3 1LA5096-6AA22-Z Nr. E 7L92 8928 01 003 0.74kW 905rpm/ min | B9: 3 | D9: 45855 | E9: Лента | G9: 45813.234 | H9: НОВ | J9: FILKAB | P9: =Table1[[#This Row],[Цена за 1 бр. в BGN]]*Table1[[#This Row],[Поръчано Количество]] -> 0 | S9: {=_xlfn.SWITCH(T9, "ivelikov@septona-bg.com", "Ivan Velikov", "andy@skuytov.eu", "Andrean Angelov", "ialeksandrov@septona-bg.com", "Ivailo Aleksandrov", "bgeorgiev@septona-bg.com", "Boris Georgiev", "iilev@septona-bg.com", "Ivailo Iliev", "dmitev@septona-bg.com", "Dimitar Mitev", "gkanchev@septona-bgc.com", "Georgi Kanchev", "s.kuytov@skuytov.eu", "Salim Kuytov", "istoyanova@septona-bg.com", "Ivelina Stoyanova", "ddimitrova@septona-bg.com", "Doroteya Dimitrova", "smehandzhieva@septona-bg.com", "Stiliana Mehandzhieva", "Unknown" )} -> Unknown
A10: шлаух ф 8 | B10: 200 метра | D10: 45826 | E10: Корпус 6, нова поточна линия памучна лента | G10: 45824.189 | H10: Доставено | J10: viautomation | P10: =Table1[[#This Row],[Цена за 1 бр. в BGN]]*Table1[[#This Row],[Поръчано Количество]] -> 0 | S10: {=_xlfn.SWITCH(T10, "ivelikov@septona-bg.com", "Ivan Velikov", "andy@skuytov.eu", "Andrean Angelov", "ialeksandrov@septona-bg.com", "Ivailo Aleksandrov", "bgeorgiev@septona-bg.com", "Boris Georgiev", "iilev@septona-bg.com", "Ivailo Iliev", "dmitev@septona-bg.com", "Dimitar Mitev", "gkanchev@septona-bgc.com", "Georgi Kanchev", "s.kuytov@skuytov.eu", "Salim Kuytov", "istoyanova@septona-bg.com", "Ivelina Stoyanova", "ddimitrova@septona-bg.com", "Doroteya Dimitrova", "smehandzhieva@septona-bg.com", "Stiliana Mehandzhieva", "Unknown" )} -> Unknown
A11: графитни втулки (лагери ) за фурните 9 (1078407 Bushing SIGRAFNE® EK3245 DRW. 051224 Rev.A.01) | B11: 8 | C11: 4 | D11: 45827 | E11: Лента | G11: 45824.189 | H11: Доставено | I11: 17248967 | J11: sglcarbon | K11: 45917 | O11: =1.95583*791.4 -> 1547.8439 | P11: =Table1[[#This Row],[Цена за 1 бр. в BGN]]*Table1[[#This Row],[Поръчано Количество]] -> 6191.3754 | S11: {=_xlfn.SWITCH(T11, "ivelikov@septona-bg.com", "Ivan Velikov", "andy@skuytov.eu", "Andrean Angelov", "ialeksandrov@septona-bg.com", "Ivailo Aleksandrov", "bgeorgiev@septona-bg.com", "Boris Georgiev", "iilev@septona-bg.com", "Ivailo Iliev", "dmitev@septona-bg.com", "Dimitar Mitev", "gkanchev@septona-bgc.com", "Georgi Kanchev", "s.kuytov@skuytov.eu", "Salim Kuytov", "istoyanova@septona-bg.com", "Ivelina Stoyanova", "ddimitrova@septona-bg.com", "Doroteya Dimitrova", "smehandzhieva@septona-bg.com", "Stiliana Mehandzhieva", "Unknown" )} -> Unknown
A12: мотор siemens 3 1LA5107-4AA21-Z 3kW 1415rpm Nr.E 7K92 6362 05 012 | B12: 4 | D12: 45841 | E12: Лента | G12: 45826.476 | J12: FILKAB | P12: =Table1[[#This Row],[Цена за 1 бр. в BGN]]*Table1[[#This Row],[Поръчано Количество]] -> 0 | S12: {=_xlfn.SWITCH(T12, "ivelikov@septona-bg.com", "Ivan Velikov", "andy@skuytov.eu", "Andrean Angelov", "ialeksandrov@septona-bg.com", "Ivailo Aleksandrov", "bgeorgiev@septona-bg.com", "Boris Georgiev", "iilev@septona-bg.com", "Ivailo Iliev", "dmitev@septona-bg.com", "Dimitar Mitev", "gkanchev@septona-bgc.com", "Georgi Kanchev", "s.kuytov@skuytov.eu", "Salim Kuytov", "istoyanova@septona-bg.com", "Ivelina Stoyanova", "ddimitrova@septona-bg.com", "Doroteya Dimitrova", "smehandzhieva@septona-bg.com", "Stiliana Mehandzhieva", "Unknown" )} -> Unknown
A13: лагер 6005ЕЕ | B13: 12 | D13: 45840 | E13: Лента | G13: 45831.177 | H13: Доставено | I13: CT-0021 | J13: PROXTEAM | P13: =Table1[[#This Row],[Цена за 1 бр. в BGN]]*Table1[[#This Row],[Поръчано Количество]] -> 0 | S13: {=_xlfn.SWITCH(T13, "ivelikov@septona-bg.com", "Ivan Velikov", "andy@skuytov.eu", "Andrean Angelov", "ialeksandrov@septona-bg.com", "Ivailo Aleksandrov", "bgeorgiev@septona-bg.com", "Boris Georgiev", "iilev@septona-bg.com", "Ivailo Iliev", "dmitev@septona-bg.com", "Dimitar Mitev", "gkanchev@septona-bgc.com", "Georgi Kanchev", "s.kuytov@skuytov.eu", "Salim Kuytov", "istoyanova@septona-bg.com", "Ivelina Stoyanova", "ddimitrova@septona-bg.com", "Doroteya Dimitrova", "smehandzhieva@septona-bg.com", "Stiliana Mehandzhieva", "Unknown" )} -> Unknown
A14: държач на пръскалки | B14: 100 | D14: 45848 | E14: Лента | G14: 45831.179 | P14: =Table1[[#This Row],[Цена за 1 бр. в BGN]]*Table1[[#This Row],[Поръчано Количество]] -> 0 | S14: {=_xlfn.SWITCH(T14, "ivelikov@septona-bg.com", "Ivan Velikov", "andy@skuytov.eu", "Andrean Angelov", "ialeksandrov@septona-bg.com", "Ivailo Aleksandrov", "bgeorgiev@septona-bg.com", "Boris Georgiev", "iilev@septona-bg.com", "Ivailo Iliev", "dmitev@septona-bg.com", "Dimitar Mitev", "gkanchev@septona-bgc.com", "Georgi Kanchev", "s.kuytov@skuytov.eu", "Salim Kuytov", "istoyanova@septona-bg.com", "Ivelina Stoyanova", "ddimitrova@septona-bg.com", "Doroteya Dimitrova", "smehandzhieva@septona-bg.com", "Stiliana Mehandzhieva", "Unknown" )} -> Unknown
A15: мотор siemens 3 1LA5107-4AA21-Z 3kW 1415rpm Nr.E 7K92 6362 05 012 | B15: 4 | D15: 45848 | E15: Лента | G15: 45831.182 | J15: FILKAB | P15: =Table1[[#This Row],[Цена за 1 бр. в BGN]]*Table1[[#This Row],[Поръчано Количество]] -> 0 | S15: {=_xlfn.SWITCH(T15, "ivelikov@septona-bg.com", "Ivan Velikov", "andy@skuytov.eu", "Andrean Angelov", "ialeksandrov@septona-bg.com", "Ivailo Aleksandrov", "bgeorgiev@septona-bg.com", "Boris Georgiev", "iilev@septona-bg.com", "Ivailo Iliev", "dmitev@septona-bg.com", "Dimitar Mitev", "gkanchev@septona-bgc.com", "Georgi Kanchev", "s.kuytov@skuytov.eu", "Salim Kuytov", "istoyanova@septona-bg.com", "Ivelina Stoyanova", "ddimitrova@septona-bg.com", "Doroteya Dimitrova", "smehandzhieva@septona-bg.com", "Stiliana Mehandzhieva", "Unknown" )} -> Unknown
A16: Помпа дозатор за химия ЕМЕC code ACP07020K0000G00A000 DESCR. PUMP AMSCLPLUS 0720 FP 230VAC 0.18A 20.00 l/h IP65 7bar -700KPas (https://cwc.com.au/products/chemical-dosing-pumps/emec-solenoid-driven-dosing-pumps/high-viscosity-polymer-pumps/emec-amscoplus-lpv-15l-hr-10b-or-60l-hr-2b-high-viscosity-heads/) | B16: 1 | D16: 45855 | E16: Лента | G16: 45831.312 | H16: Изпратено запитване | I16: CT-0031 | J16: EMEC Srl | P16: =Table1[[#This Row],[Цена за 1 бр. в BGN]]*Table1[[#This Row],[Поръчано Количество]] -> 0 | S16: {=_xlfn.SWITCH(T16, "ivelikov@septona-bg.com", "Ivan Velikov", "andy@skuytov.eu", "Andrean Angelov", "ialeksandrov@septona-bg.com", "Ivailo Aleksandrov", "bgeorgiev@septona-bg.com", "Boris Georgiev", "iilev@septona-bg.com", "Ivailo Iliev", "dmitev@septona-bg.com", "Dimitar Mitev", "gkanchev@septona-bgc.com", "Georgi Kanchev", "s.kuytov@skuytov.eu", "Salim Kuytov", "istoyanova@septona-bg.com", "Ivelina Stoyanova", "ddimitrova@septona-bg.com", "Doroteya Dimitrova", "smehandzhieva@septona-bg.com", "Stiliana Mehandzhieva", "Unknown" )} -> Unknown
A17: балон за разширителен съд NEX 80LT 10bar ser.N 332714-032 | B17: 2 | D17: 45841 | E17: Лента | G17: 45831.314 | J17: МИКРОМАКС ТРЕЙД | P17: =Table1[[#This Row],[Цена за 1 бр. в BGN]]*Table1[[#This Row],[Поръчано Количество]] -> 0 | S17: {=_xlfn.SWITCH(T17, "ivelikov@septona-bg.com", "Ivan Velikov", "andy@skuytov.eu", "Andrean Angelov", "ialeksandrov@septona-bg.com", "Ivailo Aleksandrov", "bgeorgiev@septona-bg.com", "Boris Georgiev", "iilev@septona-bg.com", "Ivailo Iliev", "dmitev@septona-bg.com", "Dimitar Mitev", "gkanchev@septona-bgc.com", "Georgi Kanchev", "s.kuytov@skuytov.eu", "Salim Kuytov", "istoyanova@septona-bg.com", "Ivelina Stoyanova", "ddimitrova@septona-bg.com", "Doroteya Dimitrova", "smehandzhieva@septona-bg.com", "Stiliana Mehandzhieva", "Unknown" )} -> Unknown
A18: прекъсвач telemecanique AC -21A 63A Ithe 50A V3 3R0917 | B18: 2 | D18: 45841 | E18: Лента | G18: 45831.321 | J18: ЕХНАТОН | P18: =Table1[[#This Row],[Цена за 1 бр. в BGN]]*Table1[[#This Row],[Поръчано Количество]] -> 0 | S18: {=_xlfn.SWITCH(T18, "ivelikov@septona-bg.com", "Ivan Velikov", "andy@skuytov.eu", "Andrean Angelov", "ialeksandrov@septona-bg.com", "Ivailo Aleksandrov", "bgeorgiev@septona-bg.com", "Boris Georgiev", "iilev@septona-bg.com", "Ivailo Iliev", "dmitev@septona-bg.com", "Dimitar Mitev", "gkanchev@septona-bgc.com", "Georgi Kanchev", "s.kuytov@skuytov.eu", "Salim Kuytov", "istoyanova@septona-bg.com", "Ivelina Stoyanova", "ddimitrova@septona-bg.com", "Doroteya Dimitrova", "smehandzhieva@septona-bg.com", "Stiliana Mehandzhieva", "Unknown" )} -> Unknown
A19: лагер RA103-NPP INA (CES.206-19) | B19: 8 | D19: 45848 | E19: Корпус 6, нова поточна линия памучна лента | G19: 45834.183 | H19: Доставено | I19: CT-0021 | J19: PROXTEAM | P19: =Table1[[#This Row],[Цена за 1 бр. в BGN]]*Table1[[#This Row],[Поръчано Количество]] -> 0 | S19: {=_xlfn.SWITCH(T19, "ivelikov@septona-bg.com", "Ivan Velikov", "andy@skuytov.eu", "Andrean Angelov", "ialeksandrov@septona-bg.com", "Ivailo Aleksandrov", "bgeorgiev@septona-bg.com", "Boris Georgiev", "iilev@septona-bg.com", "Ivailo Iliev", "dmitev@septona-bg.com", "Dimitar Mitev", "gkanchev@septona-bgc.com", "Georgi Kanchev", "s.kuytov@skuytov.eu", "Salim Kuytov", "istoyanova@septona-bg.com", "Ivelina Stoyanova", "ddimitrova@septona-bg.com", "Doroteya Dimitrova", "smehandzhieva@septona-bg.com", "Stiliana Mehandzhieva", "Unknown" )} -> Unknown
A20: ос за редуктор (300620251_Shaft for EMEMBI) | B20: 2 | C20: 2 | D20: 45841 | E20: Корпус 6, нова поточна линия памучна лента | G20: 45834.198 | H20: Доставено | J20: Зъбонарязване - петко | P20: =Table1[[#This Row],[Цена за 1 бр. в BGN]]*Table1[[#This Row],[Поръчано Количество]] -> 0 | S20: {=_xlfn.SWITCH(T20, "ivelikov@septona-bg.com", "Ivan Velikov", "andy@skuytov.eu", "Andrean Angelov", "ialeksandrov@septona-bg.com", "Ivailo Aleksandrov", "bgeorgiev@septona-bg.com", "Boris Georgiev", "iilev@septona-bg.com", "Ivailo Iliev", "dmitev@septona-bg.com", "Dimitar Mitev", "gkanchev@septona-bgc.com", "Georgi Kanchev", "s.kuytov@skuytov.eu", "Salim Kuytov", "istoyanova@septona-bg.com", "Ivelina Stoyanova", "ddimitrova@septona-bg.com", "Doroteya Dimitrova", "smehandzhieva@septona-bg.com", "Stiliana Mehandzhieva", "Unknown" )} -> Unknown
A21: магнит винтил ORIF. 2.4 W. 3N.C PRES.10 AC | B21: 6 | D21: 45842 | E21: Лента | G21: 45835.504 | J21: МИКРОМАКС ТРЕЙД | P21: =Table1[[#This Row],[Цена за 1 бр. в BGN]]*Table1[[#This Row],[Поръчано Количество]] -> 0 | S21: {=_xlfn.SWITCH(T21, "ivelikov@septona-bg.com", "Ivan Velikov", "andy@skuytov.eu", "Andrean Angelov", "ialeksandrov@septona-bg.com", "Ivailo Aleksandrov", "bgeorgiev@septona-bg.com", "Boris Georgiev", "iilev@septona-bg.com", "Ivailo Iliev", "dmitev@septona-bg.com", "Dimitar Mitev", "gkanchev@septona-bgc.com", "Georgi Kanchev", "s.kuytov@skuytov.eu", "Salim Kuytov", "istoyanova@septona-bg.com", "Ivelina Stoyanova", "ddimitrova@septona-bg.com", "Doroteya Dimitrova", "smehandzhieva@septona-bg.com", "Stiliana Mehandzhieva", "Unknown" )} -> Unknown
A22: допълнителен контактор SCHRACK LSZ0D140F 4S/4NO | B22: 2 | D22: 45848 | E22: Лента | G22: 45836.209 | H22: Доставено | J22: Schrack.bg | P22: =Table1[[#This Row],[Цена за 1 бр. в BGN]]*Table1[[#This Row],[Поръчано Количество]] -> 0 | S22: {=_xlfn.SWITCH(T22, "ivelikov@septona-bg.com", "Ivan Velikov", "andy@skuytov.eu", "Andrean Angelov", "ialeksandrov@septona-bg.com", "Ivailo Aleksandrov", "bgeorgiev@septona-bg.com", "Boris Georgiev", "iilev@septona-bg.com", "Ivailo Iliev", "dmitev@septona-bg.com", "Dimitar Mitev", "gkanchev@septona-bgc.com", "Georgi Kanchev", "s.kuytov@skuytov.eu", "Salim Kuytov", "istoyanova@septona-bg.com", "Ivelina Stoyanova", "ddimitrova@septona-bg.com", "Doroteya Dimitrova", "smehandzhieva@septona-bg.com", "Stiliana Mehandzhieva", "Unknown" )} -> Unknown
A23: контактор SCHRACK LSD01730 AC 7,5kW 400V БОБИНА 24V 50Hz | B23: 2 | D23: 45848 | E23: Лента | G23: 45836.21 | J23: Schrack.bg | P23: =Table1[[#This Row],[Цена за 1 бр. в BGN]]*Table1[[#This Row],[Поръчано Количество]] -> 0 | S23: {=_xlfn.SWITCH(T23, "ivelikov@septona-bg.com", "Ivan Velikov", "andy@skuytov.eu", "Andrean Angelov", "ialeksandrov@septona-bg.com", "Ivailo Aleksandrov", "bgeorgiev@septona-bg.com", "Boris Georgiev", "iilev@septona-bg.com", "Ivailo Iliev", "dmitev@septona-bg.com", "Dimitar Mitev", "gkanchev@septona-bgc.com", "Georgi Kanchev", "s.kuytov@skuytov.eu", "Salim Kuytov", "istoyanova@septona-bg.com", "Ivelina Stoyanova", "ddimitrova@septona-bg.com", "Doroteya Dimitrova", "smehandzhieva@septona-bg.com", "Stiliana Mehandzhieva", "Unknown" )} -> Unknown
A24: РЕЛЕ GEM-SOL 24V 50Hz 8W | B24: 6 | D24: 45848 | E24: Лента | G24: 45836.211 | P24: =Table1[[#This Row],[Цена за 1 бр. в BGN]]*Table1[[#This Row],[Поръчано Количество]] -> 0 | S24: {=_xlfn.SWITCH(T24, "ivelikov@septona-bg.com", "Ivan Velikov", "andy@skuytov.eu", "Andrean Angelov", "ialeksandrov@septona-bg.com", "Ivailo Aleksandrov", "bgeorgiev@septona-bg.com", "Boris Georgiev", "iilev@septona-bg.com", "Ivailo Iliev", "dmitev@septona-bg.com", "Dimitar Mitev", "gkanchev@septona-bgc.com", "Georgi Kanchev", "s.kuytov@skuytov.eu", "Salim Kuytov", "istoyanova@septona-bg.com", "Ivelina Stoyanova", "ddimitrova@septona-bg.com", "Doroteya Dimitrova", "smehandzhieva@septona-bg.com", "Stiliana Mehandzhieva", "Unknown" )} -> Unknown
A25: болт вътрешен шестостен М10х65 за пакетаж | B25: 200 | C25: 200 | D25: 45841 | E25: Лента | G25: 45838.167 | H25: Доставено | J25: ИТТ | O25: =98.35/100 -> 0.9835 | P25: =Table1[[#This Row],[Цена за 1 бр. в BGN]]*Table1[[#This Row],[Поръчано Количество]] -> 196.7 | S25: {=_xlfn.SWITCH(T25, "ivelikov@septona-bg.com", "Ivan Velikov", "andy@skuytov.eu", "Andrean Angelov", "ialeksandrov@septona-bg.com", "Ivailo Aleksandrov", "bgeorgiev@septona-bg.com", "Boris Georgiev", "iilev@septona-bg.com", "Ivailo Iliev", "dmitev@septona-bg.com", "Dimitar Mitev", "gkanchev@septona-bgc.com", "Georgi Kanchev", "s.kuytov@skuytov.eu", "Salim Kuytov", "istoyanova@septona-bg.com", "Ivelina Stoyanova", "ddimitrova@septona-bg.com", "Doroteya Dimitrova", "smehandzhieva@septona-bg.com", "Stiliana Mehandzhieva", "Unknown" )} -> Unknown
A26: гайка М10 | B26: 150 | D26: 45841 | E26: Лента | G26: 45838.167 | H26: Доставено | J26: ИТТ | O26: 0.07 | P26: =Table1[[#This Row],[Цена за 1 бр. в BGN]]*Table1[[#This Row],[Поръчано Количество]] -> 0 | S26: {=_xlfn.SWITCH(T26, "ivelikov@septona-bg.com", "Ivan Velikov", "andy@skuytov.eu", "Andrean Angelov", "ialeksandrov@septona-bg.com", "Ivailo Aleksandrov", "bgeorgiev@septona-bg.com", "Boris Georgiev", "iilev@septona-bg.com", "Ivailo Iliev", "dmitev@septona-bg.com", "Dimitar Mitev", "gkanchev@septona-bgc.com", "Georgi Kanchev", "s.kuytov@skuytov.eu", "Salim Kuytov", "istoyanova@septona-bg.com", "Ivelina Stoyanova", "ddimitrova@septona-bg.com", "Doroteya Dimitrova", "smehandzhieva@septona-bg.com", "Stiliana Mehandzhieva", "Unknown" )} -> Unknown
A27: съединителни звена за верига 08В-1 | B27: 50 | D27: 45841 | E27: Лента | G27: 45838.168 | H27: Доставено | I27: CT-0021 | J27: PROXTEAM | P27: =Table1[[#This Row],[Цена за 1 бр. в BGN]]*Table1[[#This Row],[Поръчано Количество]] -> 0 | S27: {=_xlfn.SWITCH(T27, "ivelikov@septona-bg.com", "Ivan Velikov", "andy@skuytov.eu", "Andrean Angelov", "ialeksandrov@septona-bg.com", "Ivailo Aleksandrov", "bgeorgiev@septona-bg.com", "Boris Georgiev", "iilev@septona-bg.com", "Ivailo Iliev", "dmitev@septona-bg.com", "Dimitar Mitev", "gkanchev@septona-bgc.com", "Georgi Kanchev", "s.kuytov@skuytov.eu", "Salim Kuytov", "istoyanova@septona-bg.com", "Ivelina Stoyanova", "ddimitrova@septona-bg.com", "Doroteya Dimitrova", "smehandzhieva@septona-bg.com", "Stiliana Mehandzhieva", "Unknown" )} -> Unknown
A28: прозрачен шлаух ф10 | B28: 100 | D28: 45841 | E28: Лента | G28: 45838.169 | H28: Доставено | J28: viautomation | P28: =Table1[[#This Row],[Цена за 1 бр. в BGN]]*Table1[[#This Row],[Поръчано Количество]] -> 0 | S28: {=_xlfn.SWITCH(T28, "ivelikov@septona-bg.com", "Ivan Velikov", "andy@skuytov.eu", "Andrean Angelov", "ialeksandrov@septona-bg.com", "Ivailo Aleksandrov", "bgeorgiev@septona-bg.com", "Boris Georgiev", "iilev@septona-bg.com", "Ivailo Iliev", "dmitev@septona-bg.com", "Dimitar Mitev", "gkanchev@septona-bgc.com", "Georgi Kanchev", "s.kuytov@skuytov.eu", "Salim Kuytov", "istoyanova@septona-bg.com", "Ivelina Stoyanova", "ddimitrova@septona-bg.com", "Doroteya Dimitrova", "smehandzhieva@septona-bg.com", "Stiliana Mehandzhieva", "Unknown" )} -> Unknown
A29: звездогаечен ключ 14 | B29: 3 | C29: 3 | D29: 45841 | E29: Инструменти | G29: 45838.322 | H29: Доставено | J29: Bekra | M29: 45917 | N29: 3 | O29: 8.127 | P29: =Table1[[#This Row],[Цена за 1 бр. в BGN]]*Table1[[#This Row],[Поръчано Количество]] -> 24.381 | Q29: 1000455532-15.09.2025 | S29: {=_xlfn.SWITCH(T29, "ivelikov@septona-bg.com", "Ivan Velikov", "andy@skuytov.eu", "Andrean Angelov", "ialeksandrov@septona-bg.com", "Ivailo Aleksandrov", "bgeorgiev@septona-bg.com", "Boris Georgiev", "iilev@septona-bg.com", "Ivailo Iliev", "dmitev@septona-bg.com", "Dimitar Mitev", "gkanchev@septona-bgc.com", "Georgi Kanchev", "s.kuytov@skuytov.eu", "Salim Kuytov", "istoyanova@septona-bg.com", "Ivelina Stoyanova", "ddimitrova@septona-bg.com", "Doroteya Dimitrova", "smehandzhieva@septona-bg.com", "Stiliana Mehandzhieva", "Unknown" )} -> Unknown
A30: шестограм дълъг N 3 | B30: 4 | D30: 45841 | E30: Инструменти | G30: 45838.322 | H30: Доставено | I30: CT-0024 | J30: ИТТ | P30: =Table1[[#This Row],[Цена за 1 бр. в BGN]]*Table1[[#This Row],[Поръчано Количество]] -> 0 | S30: {=_xlfn.SWITCH(T30, "ivelikov@septona-bg.com", "Ivan Velikov", "andy@skuytov.eu", "Andrean Angelov", "ialeksandrov@septona-bg.com", "Ivailo Aleksandrov", "bgeorgiev@septona-bg.com", "Boris Georgiev", "iilev@septona-bg.com", "Ivailo Iliev", "dmitev@septona-bg.com", "Dimitar Mitev", "gkanchev@septona-bgc.com", "Georgi Kanchev", "s.kuytov@skuytov.eu", "Salim Kuytov", "istoyanova@septona-bg.com", "Ivelina Stoyanova", "ddimitrova@septona-bg.com", "Doroteya Dimitrova", "smehandzhieva@septona-bg.com", "Stiliana Mehandzhieva", "Unknown" )} -> Unknown
A31: шестограм дълъг N 8 | B31: 4 | D31: 45841 | E31: Инструменти | G31: 45838.322 | H31: Доставено | I31: CT-0024 | J31: RECA | P31: =Table1[[#This Row],[Цена за 1 бр. в BGN]]*Table1[[#This Row],[Поръчано Количество]] -> 0 | S31: {=_xlfn.SWITCH(T31, "ivelikov@septona-bg.com", "Ivan Velikov", "andy@skuytov.eu", "Andrean Angelov", "ialeksandrov@septona-bg.com", "Ivailo Aleksandrov", "bgeorgiev@septona-bg.com", "Boris Georgiev", "iilev@septona-bg.com", "Ivailo Iliev", "dmitev@septona-bg.com", "Dimitar Mitev", "gkanchev@septona-bgc.com", "Georgi Kanchev", "s.kuytov@skuytov.eu", "Salim Kuytov", "istoyanova@septona-bg.com", "Ivelina Stoyanova", "ddimitrova@septona-bg.com", "Doroteya Dimitrova", "smehandzhieva@septona-bg.com", "Stiliana Mehandzhieva", "Unknown" )} -> Unknown
A32: шестограм дълъг N 5 | B32: 4 | C32: 4 | D32: 45841 | E32: Инструменти | G32: 45838.323 | H32: Доставено | I32: CT-0024 | J32: Bekra | N32: 4 | O32: 3.3863 | P32: =Table1[[#This Row],[Цена за 1 бр. в BGN]]*Table1[[#This Row],[Поръчано Количество]] -> 13.5452 | S32: {=_xlfn.SWITCH(T32, "ivelikov@septona-bg.com", "Ivan Velikov", "andy@skuytov.eu", "Andrean Angelov", "ialeksandrov@septona-bg.com", "Ivailo Aleksandrov", "bgeorgiev@septona-bg.com", "Boris Georgiev", "iilev@septona-bg.com", "Ivailo Iliev", "dmitev@septona-bg.com", "Dimitar Mitev", "gkanchev@septona-bgc.com", "Georgi Kanchev", "s.kuytov@skuytov.eu", "Salim Kuytov", "istoyanova@septona-bg.com", "Ivelina Stoyanova", "ddimitrova@septona-bg.com", "Doroteya Dimitrova", "smehandzhieva@septona-bg.com", "Stiliana Mehandzhieva", "Unknown" )} -> Unknown
A33: прозрачен шлаух ф16 | B33: 10 | D33: 45841 | E33: Корпус 6, нова поточна линия памучна лента | G33: 45838.324 | H33: Доставено | I33: CT-0038 | J33: LD | P33: =Table1[[#This Row],[Цена за 1 бр. в BGN]]*Table1[[#This Row],[Поръчано Количество]] -> 0 | S33: {=_xlfn.SWITCH(T33, "ivelikov@septona-bg.com", "Ivan Velikov", "andy@skuytov.eu", "Andrean Angelov", "ialeksandrov@septona-bg.com", "Ivailo Aleksandrov", "bgeorgiev@septona-bg.com", "Boris Georgiev", "iilev@septona-bg.com", "Ivailo Iliev", "dmitev@septona-bg.com", "Dimitar Mitev", "gkanchev@septona-bgc.com", "Georgi Kanchev", "s.kuytov@skuytov.eu", "Salim Kuytov", "istoyanova@septona-bg.com", "Ivelina Stoyanova", "ddimitrova@septona-bg.com", "Doroteya Dimitrova", "smehandzhieva@septona-bg.com", "Stiliana Mehandzhieva", "Unknown" )} -> Unknown
A34: дълбоки камъни за малка тресчотка N10 Вложка удължена 1/4" BFD SW10 L-50mm 339210 | B34: 3 | D34: 45847 | E34: Инструменти | G34: 45840.265 | H34: Доставено | I34: CT-0024 | J34: Бекра ООД | P34: =Table1[[#This Row],[Цена за 1 бр. в BGN]]*Table1[[#This Row],[Поръчано Количество]] -> 0 | S34: {=_xlfn.SWITCH(T34, "ivelikov@septona-bg.com", "Ivan Velikov", "andy@skuytov.eu", "Andrean Angelov", "ialeksandrov@septona-bg.com", "Ivailo Aleksandrov", "bgeorgiev@septona-bg.com", "Boris Georgiev", "iilev@septona-bg.com", "Ivailo Iliev", "dmitev@septona-bg.com", "Dimitar Mitev", "gkanchev@septona-bgc.com", "Georgi Kanchev", "s.kuytov@skuytov.eu", "Salim Kuytov", "istoyanova@septona-bg.com", "Ivelina Stoyanova", "ddimitrova@septona-bg.com", "Doroteya Dimitrova", "smehandzhieva@septona-bg.com", "Stiliana Mehandzhieva", "Unknown" )} -> Unknown
A35: дълбоки камъни за малка тресчотка N13 Вложка удължена 1/4" BFD SW13 L-50mm 417068 | B35: 3 | C35: 3 | D35: 45846 | E35: Инструменти | G35: 45840.279 | H35: Доставено | I35: CT-0024 | J35: Бекра ООД | N35: 3 | O35: 6.4436 | P35: =Table1[[#This Row],[Цена за 1 бр. в BGN]]*Table1[[#This Row],[Поръчано Количество]] -> 19.3308 | Q35: 1000455532-15.09.2025 | S35: {=_xlfn.SWITCH(T35, "ivelikov@septona-bg.com", "Ivan Velikov", "andy@skuytov.eu", "Andrean Angelov", "ialeksandrov@septona-bg.com", "Ivailo Aleksandrov", "bgeorgiev@septona-bg.com", "Boris Georgiev", "iilev@septona-bg.com", "Ivailo Iliev", "dmitev@septona-bg.com", "Dimitar Mitev", "gkanchev@septona-bgc.com", "Georgi Kanchev", "s.kuytov@skuytov.eu", "Salim Kuytov", "istoyanova@septona-bg.com", "Ivelina Stoyanova", "ddimitrova@septona-bg.com", "Doroteya Dimitrova", "smehandzhieva@septona-bg.com", "Stiliana Mehandzhieva", "Unknown" )} -> Unknown
A36: дълбоки камъни за голяма тресчотка N15 Вложка удължена 1/4" BFD SW15 L-77mm 171394 | B36: 2 | C36: 2 | D36: 45846 | E36: Инструменти | G36: 45840.279 | H36: Доставено | I36: CT-0024 | J36: Бекра ООД | N36: 2 | O36: 11.2338 | P36: =Table1[[#This Row],[Цена за 1 бр. в BGN]]*Table1[[#This Row],[Поръчано Количество]] -> 22.4676 | Q36: 1000455532-15.09.2025 | S36: {=_xlfn.SWITCH(T36, "ivelikov@septona-bg.com", "Ivan Velikov", "andy@skuytov.eu", "Andrean Angelov", "ialeksandrov@septona-bg.com", "Ivailo Aleksandrov", "bgeorgiev@septona-bg.com", "Boris Georgiev", "iilev@septona-bg.com", "Ivailo Iliev", "dmitev@septona-bg.com", "Dimitar Mitev", "gkanchev@septona-bgc.com", "Georgi Kanchev", "s.kuytov@skuytov.eu", "Salim Kuytov", "istoyanova@septona-bg.com", "Ivelina Stoyanova", "ddimitrova@septona-bg.com", "Doroteya Dimitrova", "smehandzhieva@septona-bg.com", "Stiliana Mehandzhieva", "Unknown" )} -> Unknown
A37: камъни за малка тресчотка N13 Вложка 1/4" BFD SW13 L-25mm 372688\ | B37: 3 | C37: 3 | D37: 45840 | E37: Инструменти | G37: 45840.28 | H37: Доставено | I37: CT-0024 | J37: Бекра ООД | P37: =Table1[[#This Row],[Цена за 1 бр. в BGN]]*Table1[[#This Row],[Поръчано Количество]] -> 0 | Q37: 1000455532-15.09.2025 | S37: {=_xlfn.SWITCH(T37, "ivelikov@septona-bg.com", "Ivan Velikov", "andy@skuytov.eu", "Andrean Angelov", "ialeksandrov@septona-bg.com", "Ivailo Aleksandrov", "bgeorgiev@septona-bg.com", "Boris Georgiev", "iilev@septona-bg.com", "Ivailo Iliev", "dmitev@septona-bg.com", "Dimitar Mitev", "gkanchev@septona-bgc.com", "Georgi Kanchev", "s.kuytov@skuytov.eu", "Salim Kuytov", "istoyanova@septona-bg.com", "Ivelina Stoyanova", "ddimitrova@septona-bg.com", "Doroteya Dimitrova", "smehandzhieva@septona-bg.com", "Stiliana Mehandzhieva", "Unknown" )} -> Unknown
A38: камъни за малка тресчотка N8 Вложка 1/4" BFD SW8 L-25mm 372683 | B38: 3 | C38: 3 | D38: 45840 | E38: Инструменти | G38: 45840.281 | H38: Доставено | I38: CT-0024 | J38: Бекра ООД | N38: 3 | O38: 1.877 | P38: =Table1[[#This Row],[Цена за 1 бр. в BGN]]*Table1[[#This Row],[Поръчано Количество]] -> 5.631 | Q38: 1000455532-15.09.2025 | S38: {=_xlfn.SWITCH(T38, "ivelikov@septona-bg.com", "Ivan Velikov", "andy@skuytov.eu", "Andrean Angelov", "ialeksandrov@septona-bg.com", "Ivailo Aleksandrov", "bgeorgiev@septona-bg.com", "Boris Georgiev", "iilev@septona-bg.com", "Ivailo Iliev", "dmitev@septona-bg.com", "Dimitar Mitev", "gkanchev@septona-bgc.com", "Georgi Kanchev", "s.kuytov@skuytov.eu", "Salim Kuytov", "istoyanova@septona-bg.com", "Ivelina Stoyanova", "ddimitrova@septona-bg.com", "Doroteya Dimitrova", "smehandzhieva@septona-bg.com", "Stiliana Mehandzhieva", "Unknown" )} -> Unknown
A39: камъни за малка тресчотка N7 Вложка 1/4" BFD SW7 L-25mm 372682 | B39: 3 | C39: 3 | D39: 45840 | E39: Инструменти | G39: 45840.281 | H39: Доставено | I39: CT-0024 | J39: Бекра ООД | N39: 3 | O39: 2.0334 | P39: =Table1[[#This Row],[Цена за 1 бр. в BGN]]*Table1[[#This Row],[Поръчано Количество]] -> 6.1002 | Q39: 1000455532-15.09.2025 | S39: {=_xlfn.SWITCH(T39, "ivelikov@septona-bg.com", "Ivan Velikov", "andy@skuytov.eu", "Andrean Angelov", "ialeksandrov@septona-bg.com", "Ivailo Aleksandrov", "bgeorgiev@septona-bg.com", "Boris Georgiev", "iilev@septona-bg.com", "Ivailo Iliev", "dmitev@septona-bg.com", "Dimitar Mitev", "gkanchev@septona-bgc.com", "Georgi Kanchev", "s.kuytov@skuytov.eu", "Salim Kuytov", "istoyanova@septona-bg.com", "Ivelina Stoyanova", "ddimitrova@septona-bg.com", "Doroteya Dimitrova", "smehandzhieva@septona-bg.com", "Stiliana Mehandzhieva", "Unknown" )} -> Unknown
A40: верига 08В-1 5м | B40: 4 | C40: 4 | D40: 45854 | E40: Лента | G40: 45840.281 | H40: Доставено | I40: CT-0021 | J40: PROXTEAM | N40: 1 | O40: 45.15 | P40: =Table1[[#This Row],[Цена за 1 бр. в BGN]]*Table1[[#This Row],[Поръчано Количество]] -> 180.6 | S40: {=_xlfn.SWITCH(T40, "ivelikov@septona-bg.com", "Ivan Velikov", "andy@skuytov.eu", "Andrean Angelov", "ialeksandrov@septona-bg.com", "Ivailo Aleksandrov", "bgeorgiev@septona-bg.com", "Boris Georgiev", "iilev@septona-bg.com", "Ivailo Iliev", "dmitev@septona-bg.com", "Dimitar Mitev", "gkanchev@septona-bgc.com", "Georgi Kanchev", "s.kuytov@skuytov.eu", "Salim Kuytov", "istoyanova@septona-bg.com", "Ivelina Stoyanova", "ddimitrova@septona-bg.com", "Doroteya Dimitrova", "smehandzhieva@septona-bg.com", "Stiliana Mehandzhieva", "Unknown" )} -> Unknown
A41: дълбоки камъни за голяма тресчотка N19 ВЛОЖКА 1/2" bfd sw19 l-38MM 372732 | B41: 2 | D41: 45840 | E41: Инструменти | G41: 45840.279 | H41: Доставено | I41: CT-0024 | J41: Бекра ООД | P41: =Table1[[#This Row],[Цена за 1 бр. в BGN]]*Table1[[#This Row],[Поръчано Количество]] -> 0 | S41: {=_xlfn.SWITCH(T41, "ivelikov@septona-bg.com", "Ivan Velikov", "andy@skuytov.eu", "Andrean Angelov", "ialeksandrov@septona-bg.com", "Ivailo Aleksandrov", "bgeorgiev@septona-bg.com", "Boris Georgiev", "iilev@septona-bg.com", "Ivailo Iliev", "dmitev@septona-bg.com", "Dimitar Mitev", "gkanchev@septona-bgc.com", "Georgi Kanchev", "s.kuytov@skuytov.eu", "Salim Kuytov", "istoyanova@septona-bg.com", "Ivelina Stoyanova", "ddimitrova@septona-bg.com", "Doroteya Dimitrova", "smehandzhieva@septona-bg.com", "Stiliana Mehandzhieva", "Unknown" )} -> Unknown
A42: TRIDONIC LC57/1050/54 fixC ip snc2. Символ TME: 28004143 | B42: 6 | D42: 45848 | E42: Лента | G42: 45840.38 | J42: TME | P42: =Table1[[#This Row],[Цена за 1 бр. в BGN]]*Table1[[#This Row],[Поръчано Количество]] -> 0 | S42: {=_xlfn.SWITCH(T42, "ivelikov@septona-bg.com", "Ivan Velikov", "andy@skuytov.eu", "Andrean Angelov", "ialeksandrov@septona-bg.com", "Ivailo Aleksandrov", "bgeorgiev@septona-bg.com", "Boris Georgiev", "iilev@septona-bg.com", "Ivailo Iliev", "dmitev@septona-bg.com", "Dimitar Mitev", "gkanchev@septona-bgc.com", "Georgi Kanchev", "s.kuytov@skuytov.eu", "Salim Kuytov", "istoyanova@septona-bg.com", "Ivelina Stoyanova", "ddimitrova@septona-bg.com", "Doroteya Dimitrova", "smehandzhieva@septona-bg.com", "Stiliana Mehandzhieva", "Unknown" )} -> Unknown
...

Sheet Cotton Buds and Pads
A1: Описание артикул | B1: Желано количество | C1: Поръчано Количество | D1: Желана дата за доставка | E1: Машина | F1: Submission (UTC) | G1: Статус | H1: ID запитване | I1: Доставчик | J1: Очаквана дата на доставка | K1: Товарителница | L1: Реална доставка | M1: Доставено количество | N1: Цена за 1 бр. в BGN | O1: Сума на поръчката в BGN | P1: Фактура? | Q1: Транспортни документи | R1: Name | S1: Requester email
A2: Реле Fotek SSR-25AA | B2: 2 | D2: 45807 | E2: FALU, B&M - Клечки за уши | F2: 45796.206 | G2: Изпратено запитване | H2: CBP-0022 | I2: vallder.com | O2: =Cotton_Buds[[#This Row],[Цена за 1 бр. в BGN]]*Cotton_Buds[[#This Row],[Поръчано Количество]] -> 0 | R2: {=_xlfn.SWITCH(S2, "ivelikov@septona-bg.com", "Ivan Velikov", "andy@skuytov.eu", "Andrean Angelov", "ialeksandrov@septona-bg.com", "Ivailo Aleksandrov", "bgeorgiev@septona-bg.com", "Boris Georgiev", "iilev@septona-bg.com", "Ivailo Iliev", "dmitev@septona-bg.com", "Dimitar Mitev", "gkanchev@septona-bgc.com", "Georgi Kanchev", "s.kuytov@skuytov.eu", "Salim Kuytov", "istoyanova@septona-bg.com", "Ivelina Stoyanova", "ddimitrova@septona-bg.com", "Doroteya Dimitrova", "smehandzhieva@septona-bg.com", "Stiliana Mehandzhieva", "Unknown" )} -> Unknown
A3: Стойка за цилиндъра за езичета на бластерите 06351 | B3: 2 | C3: 2 | D3: 45722 | E3: FALU, B&M - Клечки за уши | F3: 45714.279 | G3: Доставено | I3: Зъбонарязване - петко | N3: 65 | O3: =Cotton_Buds[[#This Row],[Цена за 1 бр. в BGN]]*Cotton_Buds[[#This Row],[Поръчано Количество]] -> 130 | R3: {=_xlfn.SWITCH(S3, "ivelikov@septona-bg.com", "Ivan Velikov", "andy@skuytov.eu", "Andrean Angelov", "ialeksandrov@septona-bg.com", "Ivailo Aleksandrov", "bgeorgiev@septona-bg.com", "Boris Georgiev", "iilev@septona-bg.com", "Ivailo Iliev", "dmitev@septona-bg.com", "Dimitar Mitev", "gkanchev@septona-bgc.com", "Georgi Kanchev", "s.kuytov@skuytov.eu", "Salim Kuytov", "istoyanova@septona-bg.com", "Ivelina Stoyanova", "ddimitrova@septona-bg.com", "Doroteya Dimitrova", "smehandzhieva@septona-bg.com", "Stiliana Mehandzhieva", "Unknown" )} -> Unknown
A4: Motovario 9633156-004 NMRV 040 i 7.50 (https://www.motovario.com/eng/my-products/9633156-004) | B4: 1 | D4: 45822 | E4: FALU - Тампони | F4: 45796.444 | I4: Alexandris | O4: =Cotton_Buds[[#This Row],[Цена за 1 бр. в BGN]]*Cotton_Buds[[#This Row],[Поръчано Количество]] -> 0 | R4: {=_xlfn.SWITCH(S4, "ivelikov@septona-bg.com", "Ivan Velikov", "andy@skuytov.eu", "Andrean Angelov", "ialeksandrov@septona-bg.com", "Ivailo Aleksandrov", "bgeorgiev@septona-bg.com", "Boris Georgiev", "iilev@septona-bg.com", "Ivailo Iliev", "dmitev@septona-bg.com", "Dimitar Mitev", "gkanchev@septona-bgc.com", "Georgi Kanchev", "s.kuytov@skuytov.eu", "Salim Kuytov", "istoyanova@septona-bg.com", "Ivelina Stoyanova", "ddimitrova@septona-bg.com", "Doroteya Dimitrova", "smehandzhieva@septona-bg.com", "Stiliana Mehandzhieva", "Unknown" )} -> Unknown
A5: Разпределител серия EN, EN531-11-PN3 CAMOZZI (ACM 12) | B5: 5 | C5: 5 | D5: 45722 | E5: ACM | F5: 45714.44 | G5: Доставено | H5: CBP-0005 | SQ158222 | I5: LD | J5: 45737 | L5: 45737 | N5: 159.3 | O5: =Cotton_Buds[[#This Row],[Цена за 1 бр. в BGN]]*Cotton_Buds[[#This Row],[Поръчано Количество]] -> 796.5 | R5: {=_xlfn.SWITCH(S5, "ivelikov@septona-bg.com", "Ivan Velikov", "andy@skuytov.eu", "Andrean Angelov", "ialeksandrov@septona-bg.com", "Ivailo Aleksandrov", "bgeorgiev@septona-bg.com", "Boris Georgiev", "iilev@septona-bg.com", "Ivailo Iliev", "dmitev@septona-bg.com", "Dimitar Mitev", "gkanchev@septona-bgc.com", "Georgi Kanchev", "s.kuytov@skuytov.eu", "Salim Kuytov", "istoyanova@septona-bg.com", "Ivelina Stoyanova", "ddimitrova@septona-bg.com", "Doroteya Dimitrova", "smehandzhieva@septona-bg.com", "Stiliana Mehandzhieva", "Unknown" )} -> Unknown
A6: имбусен болт M4x8 | B6: 500 | C6: 500 | D6: 45716 | E6: FALU, B&M - Клечки за уши | F6: 45714.546 | G6: Доставено | H6: 161900 | I6: ИТТ | J6: 45722 | L6: 45722 | M6: 500 | N6: 0.12348 | O6: =Cotton_Buds[[#This Row],[Цена за 1 бр. в BGN]]*Cotton_Buds[[#This Row],[Поръчано Количество]] -> 61.74 | R6: {=_xlfn.SWITCH(S6, "ivelikov@septona-bg.com", "Ivan Velikov", "andy@skuytov.eu", "Andrean Angelov", "ialeksandrov@septona-bg.com", "Ivailo Aleksandrov", "bgeorgiev@septona-bg.com", "Boris Georgiev", "iilev@septona-bg.com", "Ivailo Iliev", "dmitev@septona-bg.com", "Dimitar Mitev", "gkanchev@septona-bgc.com", "Georgi Kanchev", "s.kuytov@skuytov.eu", "Salim Kuytov", "istoyanova@septona-bg.com", "Ivelina Stoyanova", "ddimitrova@septona-bg.com", "Doroteya Dimitrova", "smehandzhieva@septona-bg.com", "Stiliana Mehandzhieva", "Unknown" )} -> Unknown
A7: Електромотор 0,37 kW, 1450 rpm, Ø14 ос изходяща да е съвместим със Motovario 9633156-004 NMRV 040 i 7.50 (https://www.motovario.com/eng/my-products/9633156-004) | B7: 1 | D7: 45822 | E7: FALU - Тампони | F7: 45796.446 | I7: Alexandris | O7: =Cotton_Buds[[#This Row],[Цена за 1 бр. в BGN]]*Cotton_Buds[[#This Row],[Поръчано Количество]] -> 0 | R7: {=_xlfn.SWITCH(S7, "ivelikov@septona-bg.com", "Ivan Velikov", "andy@skuytov.eu", "Andrean Angelov", "ialeksandrov@septona-bg.com", "Ivailo Aleksandrov", "bgeorgiev@septona-bg.com", "Boris Georgiev", "iilev@septona-bg.com", "Ivailo Iliev", "dmitev@septona-bg.com", "Dimitar Mitev", "gkanchev@septona-bgc.com", "Georgi Kanchev", "s.kuytov@skuytov.eu", "Salim Kuytov", "istoyanova@septona-bg.com", "Ivelina Stoyanova", "ddimitrova@septona-bg.com", "Doroteya Dimitrova", "smehandzhieva@septona-bg.com", "Stiliana Mehandzhieva", "Unknown" )} -> Unknown
A8: Зъбно колело 3.000.0002 | B8: 2 | D8: 45812 | E8: ACM | F8: 45801.276 | G8: НОВ | I8: ACM Engineering | O8: =Cotton_Buds[[#This Row],[Цена за 1 бр. в BGN]]*Cotton_Buds[[#This Row],[Поръчано Количество]] -> 0 | R8: {=_xlfn.SWITCH(S8, "ivelikov@septona-bg.com", "Ivan Velikov", "andy@skuytov.eu", "Andrean Angelov", "ialeksandrov@septona-bg.com", "Ivailo Aleksandrov", "bgeorgiev@septona-bg.com", "Boris Georgiev", "iilev@septona-bg.com", "Ivailo Iliev", "dmitev@septona-bg.com", "Dimitar Mitev", "gkanchev@septona-bgc.com", "Georgi Kanchev", "s.kuytov@skuytov.eu", "Salim Kuytov", "istoyanova@septona-bg.com", "Ivelina Stoyanova", "ddimitrova@septona-bg.com", "Doroteya Dimitrova", "smehandzhieva@septona-bg.com", "Stiliana Mehandzhieva", "Unknown" )} -> Unknown
A9: Зъбно колело 3.000.0002 | B9: 2 | D9: 45812 | E9: ACM | F9: 45801.277 | G9: НОВ | I9: ACM Engineering | O9: =Cotton_Buds[[#This Row],[Цена за 1 бр. в BGN]]*Cotton_Buds[[#This Row],[Поръчано Количество]] -> 0 | R9: {=_xlfn.SWITCH(S9, "ivelikov@septona-bg.com", "Ivan Velikov", "andy@skuytov.eu", "Andrean Angelov", "ialeksandrov@septona-bg.com", "Ivailo Aleksandrov", "bgeorgiev@septona-bg.com", "Boris Georgiev", "iilev@septona-bg.com", "Ivailo Iliev", "dmitev@septona-bg.com", "Dimitar Mitev", "gkanchev@septona-bgc.com", "Georgi Kanchev", "s.kuytov@skuytov.eu", "Salim Kuytov", "istoyanova@septona-bg.com", "Ivelina Stoyanova", "ddimitrova@septona-bg.com", "Doroteya Dimitrova", "smehandzhieva@septona-bg.com", "Stiliana Mehandzhieva", "Unknown" )} -> Unknown
A10: Силикон за насрещния за лепене на пликове 10mmx10mmx38cm | B10: 8 | D10: 45723 | E10: Топчета | F10: 45716.217 | G10: Доставено | I10: МИКРОМАКС ТРЕЙД | O10: =Cotton_Buds[[#This Row],[Цена за 1 бр. в BGN]]*Cotton_Buds[[#This Row],[Поръчано Количество]] -> 0 | R10: {=_xlfn.SWITCH(S10, "ivelikov@septona-bg.com", "Ivan Velikov", "andy@skuytov.eu", "Andrean Angelov", "ialeksandrov@septona-bg.com", "Ivailo Aleksandrov", "bgeorgiev@septona-bg.com", "Boris Georgiev", "iilev@septona-bg.com", "Ivailo Iliev", "dmitev@septona-bg.com", "Dimitar Mitev", "gkanchev@septona-bgc.com", "Georgi Kanchev", "s.kuytov@skuytov.eu", "Salim Kuytov", "istoyanova@septona-bg.com", "Ivelina Stoyanova", "ddimitrova@septona-bg.com", "Doroteya Dimitrova", "smehandzhieva@septona-bg.com", "Stiliana Mehandzhieva", "Unknown" )} -> Unknown
A11: Тъмно син спрей за палетите | B11: 6 | C11: 8 | D11: 45723 | E11: ОТК | F11: 45716.221 | G11: Доставено | N11: 5 | O11: =Cotton_Buds[[#This Row],[Цена за 1 бр. в BGN]]*Cotton_Buds[[#This Row],[Поръчано Количество]] -> 40 | R11: {=_xlfn.SWITCH(S11, "ivelikov@septona-bg.com", "Ivan Velikov", "andy@skuytov.eu", "Andrean Angelov", "ialeksandrov@septona-bg.com", "Ivailo Aleksandrov", "bgeorgiev@septona-bg.com", "Boris Georgiev", "iilev@septona-bg.com", "Ivailo Iliev", "dmitev@septona-bg.com", "Dimitar Mitev", "gkanchev@septona-bgc.com", "Georgi Kanchev", "s.kuytov@skuytov.eu", "Salim Kuytov", "istoyanova@septona-bg.com", "Ivelina Stoyanova", "ddimitrova@septona-bg.com", "Doroteya Dimitrova", "smehandzhieva@septona-bg.com", "Stiliana Mehandzhieva", "Unknown" )} -> Unknown
A12: Шестограм 3 | B12: 10 | D12: 45723 | E12: Инструменти | F12: 45716.222 | G12: Доставено | I12: RECA | O12: =Cotton_Buds[[#This Row],[Цена за 1 бр. в BGN]]*Cotton_Buds[[#This Row],[Поръчано Количество]] -> 0 | R12: {=_xlfn.SWITCH(S12, "ivelikov@septona-bg.com", "Ivan Velikov", "andy@skuytov.eu", "Andrean Angelov", "ialeksandrov@septona-bg.com", "Ivailo Aleksandrov", "bgeorgiev@septona-bg.com", "Boris Georgiev", "iilev@septona-bg.com", "Ivailo Iliev", "dmitev@septona-bg.com", "Dimitar Mitev", "gkanchev@septona-bgc.com", "Georgi Kanchev", "s.kuytov@skuytov.eu", "Salim Kuytov", "istoyanova@septona-bg.com", "Ivelina Stoyanova", "ddimitrova@septona-bg.com", "Doroteya Dimitrova", "smehandzhieva@septona-bg.com", "Stiliana Mehandzhieva", "Unknown" )} -> Unknown
A13: 3.000.0003 | B13: 2 | D13: 45812 | E13: ACM | F13: 45801.278 | G13: НОВ | I13: ACM Engineering | O13: =Cotton_Buds[[#This Row],[Цена за 1 бр. в BGN]]*Cotton_Buds[[#This Row],[Поръчано Количество]] -> 0 | R13: {=_xlfn.SWITCH(S13, "ivelikov@septona-bg.com", "Ivan Velikov", "andy@skuytov.eu", "Andrean Angelov", "ialeksandrov@septona-bg.com", "Ivailo Aleksandrov", "bgeorgiev@septona-bg.com", "Boris Georgiev", "iilev@septona-bg.com", "Ivailo Iliev", "dmitev@septona-bg.com", "Dimitar Mitev", "gkanchev@septona-bgc.com", "Georgi Kanchev", "s.kuytov@skuytov.eu", "Salim Kuytov", "istoyanova@septona-bg.com", "Ivelina Stoyanova", "ddimitrova@septona-bg.com", "Doroteya Dimitrova", "smehandzhieva@septona-bg.com", "Stiliana Mehandzhieva", "Unknown" )} -> Unknown
A14: Цилиндър ADVU-25-80-A-P-A --> ADN-25-80-A-P-A 576652 | B14: 2 | C14: 2 | D14: 45723 | E14: FALU, B&M - Клечки за уши | F14: 45716.223 | G14: Доставено | H14: CBP & CT 0001/2535091440 | I14: FESTO | N14: 91.43 | O14: =Cotton_Buds[[#This Row],[Цена за 1 бр. в BGN]]*Cotton_Buds[[#This Row],[Поръчано Количество]] -> 182.86 | R14: {=_xlfn.SWITCH(S14, "ivelikov@septona-bg.com", "Ivan Velikov", "andy@skuytov.eu", "Andrean Angelov", "ialeksandrov@septona-bg.com", "Ivailo Aleksandrov", "bgeorgiev@septona-bg.com", "Boris Georgiev", "iilev@septona-bg.com", "Ivailo Iliev", "dmitev@septona-bg.com", "Dimitar Mitev", "gkanchev@septona-bgc.com", "Georgi Kanchev", "s.kuytov@skuytov.eu", "Salim Kuytov", "istoyanova@septona-bg.com", "Ivelina Stoyanova", "ddimitrova@septona-bg.com", "Doroteya Dimitrova", "smehandzhieva@septona-bg.com", "Stiliana Mehandzhieva", "Unknown" )} -> Unknown
A15: Ремък 700 H | B15: 3 | C15: 3 | D15: 45821 | E15: FALU, B&M - Клечки за уши | F15: 45805.158 | G15: Доставено | H15: CBP-0040 | I15: PROXTEAM | O15: =Cotton_Buds[[#This Row],[Цена за 1 бр. в BGN]]*Cotton_Buds[[#This Row],[Поръчано Количество]] -> 0 | R15: {=_xlfn.SWITCH(S15, "ivelikov@septona-bg.com", "Ivan Velikov", "andy@skuytov.eu", "Andrean Angelov", "ialeksandrov@septona-bg.com", "Ivailo Aleksandrov", "bgeorgiev@septona-bg.com", "Boris Georgiev", "iilev@septona-bg.com", "Ivailo Iliev", "dmitev@septona-bg.com", "Dimitar Mitev", "gkanchev@septona-bgc.com", "Georgi Kanchev", "s.kuytov@skuytov.eu", "Salim Kuytov", "istoyanova@septona-bg.com", "Ivelina Stoyanova", "ddimitrova@septona-bg.com", "Doroteya Dimitrova", "smehandzhieva@septona-bg.com", "Stiliana Mehandzhieva", "Unknown" )} -> Unknown
A16: Шайби 4 | B16: 50 | C16: 50 | D16: 45812 | E16: Общи | F16: 45806.396 | G16: Доставено | H16: 177751 | I16: ИТТ | J16: 45835 | L16: 45835 | M16: 50 | N16: =0.15/50 -> 0.003 | O16: =Cotton_Buds[[#This Row],[Цена за 1 бр. в BGN]]*Cotton_Buds[[#This Row],[Поръчано Количество]] -> 0.15 | R16: {=_xlfn.SWITCH(S16, "ivelikov@septona-bg.com", "Ivan Velikov", "andy@skuytov.eu", "Andrean Angelov", "ialeksandrov@septona-bg.com", "Ivailo Aleksandrov", "bgeorgiev@septona-bg.com", "Boris Georgiev", "iilev@septona-bg.com", "Ivailo Iliev", "dmitev@septona-bg.com", "Dimitar Mitev", "gkanchev@septona-bgc.com", "Georgi Kanchev", "s.kuytov@skuytov.eu", "Salim Kuytov", "istoyanova@septona-bg.com", "Ivelina Stoyanova", "ddimitrova@septona-bg.com", "Doroteya Dimitrova", "smehandzhieva@septona-bg.com", "Stiliana Mehandzhieva", "Unknown" )} -> Unknown
A17: Шайби 6 | B17: 50 | C17: 50 | D17: 45812 | E17: Общи | F17: 45806.396 | G17: Доставено | H17: 177751 | I17: ИТТ | J17: 45835 | L17: 45835 | M17: 50 | N17: =0.28/50 -> 0.0056 | O17: =Cotton_Buds[[#This Row],[Цена за 1 бр. в BGN]]*Cotton_Buds[[#This Row],[Поръчано Количество]] -> 0.28 | R17: {=_xlfn.SWITCH(S17, "ivelikov@septona-bg.com", "Ivan Velikov", "andy@skuytov.eu", "Andrean Angelov", "ialeksandrov@septona-bg.com", "Ivailo Aleksandrov", "bgeorgiev@septona-bg.com", "Boris Georgiev", "iilev@septona-bg.com", "Ivailo Iliev", "dmitev@septona-bg.com", "Dimitar Mitev", "gkanchev@septona-bgc.com", "Georgi Kanchev", "s.kuytov@skuytov.eu", "Salim Kuytov", "istoyanova@septona-bg.com", "Ivelina Stoyanova", "ddimitrova@septona-bg.com", "Doroteya Dimitrova", "smehandzhieva@septona-bg.com", "Stiliana Mehandzhieva", "Unknown" )} -> Unknown
A18: Гайки 4mm | B18: 50 | C18: 50 | D18: 45812 | E18: Общи | F18: 45806.397 | G18: Доставено | H18: 177751 | I18: ИТТ | J18: 45835 | L18: 45835 | M18: 50 | N18: =0.2/50 -> 0.004 | O18: =Cotton_Buds[[#This Row],[Цена за 1 бр. в BGN]]*Cotton_Buds[[#This Row],[Поръчано Количество]] -> 0.2 | R18: {=_xlfn.SWITCH(S18, "ivelikov@septona-bg.com", "Ivan Velikov", "andy@skuytov.eu", "Andrean Angelov", "ialeksandrov@septona-bg.com", "Ivailo Aleksandrov", "bgeorgiev@septona-bg.com", "Boris Georgiev", "iilev@septona-bg.com", "Ivailo Iliev", "dmitev@septona-bg.com", "Dimitar Mitev", "gkanchev@septona-bgc.com", "Georgi Kanchev", "s.kuytov@skuytov.eu", "Salim Kuytov", "istoyanova@septona-bg.com", "Ivelina Stoyanova", "ddimitrova@septona-bg.com", "Doroteya Dimitrova", "smehandzhieva@septona-bg.com", "Stiliana Mehandzhieva", "Unknown" )} -> Unknown
A19: Изключвател ZCMD21L2 (XCMD2110L2) Telemanique | B19: 2 | D19: 45723 | E19: ACM | F19: 45716.228 | G19: Доставено | I19: ЕХНАТОН | O19: =Cotton_Buds[[#This Row],[Цена за 1 бр. в BGN]]*Cotton_Buds[[#This Row],[Поръчано Количество]] -> 0 | R19: {=_xlfn.SWITCH(S19, "ivelikov@septona-bg.com", "Ivan Velikov", "andy@skuytov.eu", "Andrean Angelov", "ialeksandrov@septona-bg.com", "Ivailo Aleksandrov", "bgeorgiev@septona-bg.com", "Boris Georgiev", "iilev@septona-bg.com", "Ivailo Iliev", "dmitev@septona-bg.com", "Dimitar Mitev", "gkanchev@septona-bgc.com", "Georgi Kanchev", "s.kuytov@skuytov.eu", "Salim Kuytov", "istoyanova@septona-bg.com", "Ivelina Stoyanova", "ddimitrova@septona-bg.com", "Doroteya Dimitrova", "smehandzhieva@septona-bg.com", "Stiliana Mehandzhieva", "Unknown" )} -> Unknown
A20: Лагер 6201 | B20: 20 | C20: 20 | D20: 45723 | E20: FALU, B&M - Клечки за уши | F20: 45716.23 | G20: Доставено | H20: CM-0002 | I20: Кастел Карлово | J20: 45771 | L20: 45771 | M20: 20 | N20: 2.3 | O20: =Cotton_Buds[[#This Row],[Цена за 1 бр. в BGN]]*Cotton_Buds[[#This Row],[Поръчано Количество]] -> 46 | R20: {=_xlfn.SWITCH(S20, "ivelikov@septona-bg.com", "Ivan Velikov", "andy@skuytov.eu", "Andrean Angelov", "ialeksandrov@septona-bg.com", "Ivailo Aleksandrov", "bgeorgiev@septona-bg.com", "Boris Georgiev", "iilev@septona-bg.com", "Ivailo Iliev", "dmitev@septona-bg.com", "Dimitar Mitev", "gkanchev@septona-bgc.com", "Georgi Kanchev", "s.kuytov@skuytov.eu", "Salim Kuytov", "istoyanova@septona-bg.com", "Ivelina Stoyanova", "ddimitrova@septona-bg.com", "Doroteya Dimitrova", "smehandzhieva@septona-bg.com", "Stiliana Mehandzhieva", "Unknown" )} -> Unknown
A21: Цилиндър Metal Work 2410250040XP | B21: 4 | D21: 45812 | E21: ACM | F21: 45806.406 | G21: НОВ | I21: kamatic | O21: =Cotton_Buds[[#This Row],[Цена за 1 бр. в BGN]]*Cotton_Buds[[#This Row],[Поръчано Количество]] -> 0 | R21: {=_xlfn.SWITCH(S21, "ivelikov@septona-bg.com", "Ivan Velikov", "andy@skuytov.eu", "Andrean Angelov", "ialeksandrov@septona-bg.com", "Ivailo Aleksandrov", "bgeorgiev@septona-bg.com", "Boris Georgiev", "iilev@septona-bg.com", "Ivailo Iliev", "dmitev@septona-bg.com", "Dimitar Mitev", "gkanchev@septona-bgc.com", "Georgi Kanchev", "s.kuytov@skuytov.eu", "Salim Kuytov", "istoyanova@septona-bg.com", "Ivelina Stoyanova", "ddimitrova@septona-bg.com", "Doroteya Dimitrova", "smehandzhieva@septona-bg.com", "Stiliana Mehandzhieva", "Unknown" )} -> Unknown
A22: Metal Work 121A500050CP | B22: 2 | C22: 2 | D22: 45723 | E22: ACM | F22: 45716.233 | G22: Доставено | I22: kamatic | J22: 45740 | N22: 137.6 | O22: =Cotton_Buds[[#This Row],[Цена за 1 бр. в BGN]]*Cotton_Buds[[#This Row],[Поръчано Количество]] -> 275.2 | R22: {=_xlfn.SWITCH(S22, "ivelikov@septona-bg.com", "Ivan Velikov", "andy@skuytov.eu", "Andrean Angelov", "ialeksandrov@septona-bg.com", "Ivailo Aleksandrov", "bgeorgiev@septona-bg.com", "Boris Georgiev", "iilev@septona-bg.com", "Ivailo Iliev", "dmitev@septona-bg.com", "Dimitar Mitev", "gkanchev@septona-bgc.com", "Georgi Kanchev", "s.kuytov@skuytov.eu", "Salim Kuytov", "istoyanova@septona-bg.com", "Ivelina Stoyanova", "ddimitrova@septona-bg.com", "Doroteya Dimitrova", "smehandzhieva@septona-bg.com", "Stiliana Mehandzhieva", "Unknown" )} -> Unknown
A23: RKC 4.4T-5/TEL - кабел за датчик | B23: 5 | C23: 5 | D23: 45723 | E23: FALU, B&M - Клечки за уши | F23: 45716.234 | G23: Доставено | H23: CBP-0011 | 39275 | I23: SENSOMAT | J23: 45777 | N23: 19.76 | O23: =Cotton_Buds[[#This Row],[Цена за 1 бр. в BGN]]*Cotton_Buds[[#This Row],[Поръчано Количество]] -> 98.8 | R23: {=_xlfn.SWITCH(S23, "ivelikov@septona-bg.com", "Ivan Velikov", "andy@skuytov.eu", "Andrean Angelov", "ialeksandrov@septona-bg.com", "Ivailo Aleksandrov", "bgeorgiev@septona-bg.com", "Boris Georgiev", "iilev@septona-bg.com", "Ivailo Iliev", "dmitev@septona-bg.com", "Dimitar Mitev", "gkanchev@septona-bgc.com", "Georgi Kanchev", "s.kuytov@skuytov.eu", "Salim Kuytov", "istoyanova@septona-bg.com", "Ivelina Stoyanova", "ddimitrova@septona-bg.com", "Doroteya Dimitrova", "smehandzhieva@septona-bg.com", "Stiliana Mehandzhieva", "Unknown" )} -> Unknown
A24: Mobil SHC Cibus 150 20Lit | B24: 2 | D24: 45723 | E24: FALU, B&M - Клечки за уши | F24: 45716.235 | G24: Доставено | I24: ОМНИКАР БГ ЕООД | O24: =Cotton_Buds[[#This Row],[Цена за 1 бр. в BGN]]*Cotton_Buds[[#This Row],[Поръчано Количество]] -> 0 | R24: {=_xlfn.SWITCH(S24, "ivelikov@septona-bg.com", "Ivan Velikov", "andy@skuytov.eu", "Andrean Angelov", "ialeksandrov@septona-bg.com", "Ivailo Aleksandrov", "bgeorgiev@septona-bg.com", "Boris Georgiev", "iilev@septona-bg.com", "Ivailo Iliev", "dmitev@septona-bg.com", "Dimitar Mitev", "gkanchev@septona-bgc.com", "Georgi Kanchev", "s.kuytov@skuytov.eu", "Salim Kuytov", "istoyanova@septona-bg.com", "Ivelina Stoyanova", "ddimitrova@septona-bg.com", "Doroteya Dimitrova", "smehandzhieva@septona-bg.com", "Stiliana Mehandzhieva", "Unknown" )} -> Unknown
A25: Болтове за поасона | B25: 20 | D25: 45814 | E25: FALU - Тампони | F25: 45806.407 | G25: НОВ | O25: =Cotton_Buds[[#This Row],[Цена за 1 бр. в BGN]]*Cotton_Buds[[#This Row],[Поръчано Количество]] -> 0 | R25: {=_xlfn.SWITCH(S25, "ivelikov@septona-bg.com", "Ivan Velikov", "andy@skuytov.eu", "Andrean Angelov", "ialeksandrov@septona-bg.com", "Ivailo Aleksandrov", "bgeorgiev@septona-bg.com", "Boris Georgiev", "iilev@septona-bg.com", "Ivailo Iliev", "dmitev@septona-bg.com", "Dimitar Mitev", "gkanchev@septona-bgc.com", "Georgi Kanchev", "s.kuytov@skuytov.eu", "Salim Kuytov", "istoyanova@septona-bg.com", "Ivelina Stoyanova", "ddimitrova@septona-bg.com", "Doroteya Dimitrova", "smehandzhieva@septona-bg.com", "Stiliana Mehandzhieva", "Unknown" )} -> Unknown
A26: 222.204.103 Plain Bearing iglidur Ø08/10x10 - P210SM-0810-10 | B26: 20 | D26: 45814 | E26: FALU, B&M - Клечки за уши | F26: 45806.428 | G26: НОВ | I26: Hennlich | O26: =Cotton_Buds[[#This Row],[Цена за 1 бр. в BGN]]*Cotton_Buds[[#This Row],[Поръчано Количество]] -> 0 | R26: {=_xlfn.SWITCH(S26, "ivelikov@septona-bg.com", "Ivan Velikov", "andy@skuytov.eu", "Andrean Angelov", "ialeksandrov@septona-bg.com", "Ivailo Aleksandrov", "bgeorgiev@septona-bg.com", "Boris Georgiev", "iilev@septona-bg.com", "Ivailo Iliev", "dmitev@septona-bg.com", "Dimitar Mitev", "gkanchev@septona-bgc.com", "Georgi Kanchev", "s.kuytov@skuytov.eu", "Salim Kuytov", "istoyanova@septona-bg.com", "Ivelina Stoyanova", "ddimitrova@septona-bg.com", "Doroteya Dimitrova", "smehandzhieva@septona-bg.com", "Stiliana Mehandzhieva", "Unknown" )} -> Unknown
A27: Болтове М5/М6 — 10/16/20/25 | B27: 50 | D27: 45818 | E27: Общи | F27: 45812.272 | G27: Доставено | I27: ИТТ | O27: =Cotton_Buds[[#This Row],[Цена за 1 бр. в BGN]]*Cotton_Buds[[#This Row],[Поръчано Количество]] -> 0 | R27: {=_xlfn.SWITCH(S27, "ivelikov@septona-bg.com", "Ivan Velikov", "andy@skuytov.eu", "Andrean Angelov", "ialeksandrov@septona-bg.com", "Ivailo Aleksandrov", "bgeorgiev@septona-bg.com", "Boris Georgiev", "iilev@septona-bg.com", "Ivailo Iliev", "dmitev@septona-bg.com", "Dimitar Mitev", "gkanchev@septona-bgc.com", "Georgi Kanchev", "s.kuytov@skuytov.eu", "Salim Kuytov", "istoyanova@septona-bg.com", "Ivelina Stoyanova", "ddimitrova@septona-bg.com", "Doroteya Dimitrova", "smehandzhieva@septona-bg.com", "Stiliana Mehandzhieva", "Unknown" )} -> Unknown
A28: Кръстат ключ за ел. табла | B28: 3 | D28: 45736 | E28: Инструменти | F28: 45721.325 | G28: Доставено | I28: RECA | O28: =Cotton_Buds[[#This Row],[Цена за 1 бр. в BGN]]*Cotton_Buds[[#This Row],[Поръчано Количество]] -> 0 | R28: {=_xlfn.SWITCH(S28, "ivelikov@septona-bg.com", "Ivan Velikov", "andy@skuytov.eu", "Andrean Angelov", "ialeksandrov@septona-bg.com", "Ivailo Aleksandrov", "bgeorgiev@septona-bg.com", "Boris Georgiev", "iilev@septona-bg.com", "Ivailo Iliev", "dmitev@septona-bg.com", "Dimitar Mitev", "gkanchev@septona-bgc.com", "Georgi Kanchev", "s.kuytov@skuytov.eu", "Salim Kuytov", "istoyanova@septona-bg.com", "Ivelina Stoyanova", "ddimitrova@septona-bg.com", "Doroteya Dimitrova", "smehandzhieva@septona-bg.com", "Stiliana Mehandzhieva", "Unknown" )} -> Unknown
A29: Лист за ножовка, Bi-Metal, 24TPI, 12.5 x 300 мм, 2 бр HG HT3S280 | B29: 4 | C29: 4 | D29: 45729 | E29: Инструменти | F29: 45721.327 | G29: Доставено | H29: 162689 | I29: ИТТ | J29: 45728 | L29: 45728 | M29: 4 | N29: =4.76/2 -> 2.38 | O29: =Cotton_Buds[[#This Row],[Цена за 1 бр. в BGN]]*Cotton_Buds[[#This Row],[Поръчано Количество]] -> 9.52 | R29: {=_xlfn.SWITCH(S29, "ivelikov@septona-bg.com", "Ivan Velikov", "andy@skuytov.eu", "Andrean Angelov", "ialeksandrov@septona-bg.com", "Ivailo Aleksandrov", "bgeorgiev@septona-bg.com", "Boris Georgiev", "iilev@septona-bg.com", "Ivailo Iliev", "dmitev@septona-bg.com", "Dimitar Mitev", "gkanchev@septona-bgc.com", "Georgi Kanchev", "s.kuytov@skuytov.eu", "Salim Kuytov", "istoyanova@septona-bg.com", "Ivelina Stoyanova", "ddimitrova@septona-bg.com", "Doroteya Dimitrova", "smehandzhieva@septona-bg.com", "Stiliana Mehandzhieva", "Unknown" )} -> Unknown
A30: DSNU-25-228-PPV-A | B30: 3 | C30: 3 | D30: 45722 | E30: ACM | F30: 45721.331 | G30: Доставено | H30: 2535091031 | I30: FESTO | J30: 45735 | L30: 45726 | N30: 120.95 | O30: =Cotton_Buds[[#This Row],[Цена за 1 бр. в BGN]]*Cotton_Buds[[#This Row],[Поръчано Количество]] -> 362.85 | P30: 1460230406 | R30: {=_xlfn.SWITCH(S30, "ivelikov@septona-bg.com", "Ivan Velikov", "andy@skuytov.eu", "Andrean Angelov", "ialeksandrov@septona-bg.com", "Ivailo Aleksandrov", "bgeorgiev@septona-bg.com", "Boris Georgiev", "iilev@septona-bg.com", "Ivailo Iliev", "dmitev@septona-bg.com", "Dimitar Mitev", "gkanchev@septona-bgc.com", "Georgi Kanchev", "s.kuytov@skuytov.eu", "Salim Kuytov", "istoyanova@septona-bg.com", "Ivelina Stoyanova", "ddimitrova@septona-bg.com", "Doroteya Dimitrova", "smehandzhieva@septona-bg.com", "Stiliana Mehandzhieva", "Unknown" )} -> Unknown
A31: мотор seipee type JM90LA2B5 --> K20279 BONFIGLIOLI BE 90L 2 230/400-50 IP55 CLF B5 триф.ел.мотор IE2 P=2.2kW n=2870min-1 | B31: 1 | C31: 1 | D31: 45721 | E31: Инструменти | F31: 45721.535 | G31: Доставено | H31: CBP-0003 | I31: УЛМЕР | J31: 45724 | K31: SPEEDY - 63017193674 | L31: 45724 | N31: 509 | O31: =Cotton_Buds[[#This Row],[Цена за 1 бр. в BGN]]*Cotton_Buds[[#This Row],[Поръчано Количество]] -> 509 | R31: {=_xlfn.SWITCH(S31, "ivelikov@septona-bg.com", "Ivan Velikov", "andy@skuytov.eu", "Andrean Angelov", "ialeksandrov@septona-bg.com", "Ivailo Aleksandrov", "bgeorgiev@septona-bg.com", "Boris Georgiev", "iilev@septona-bg.com", "Ivailo Iliev", "dmitev@septona-bg.com", "Dimitar Mitev", "gkanchev@septona-bgc.com", "Georgi Kanchev", "s.kuytov@skuytov.eu", "Salim Kuytov", "istoyanova@septona-bg.com", "Ivelina Stoyanova", "ddimitrova@septona-bg.com", "Doroteya Dimitrova", "smehandzhieva@septona-bg.com", "Stiliana Mehandzhieva", "Unknown" )} -> Unknown
A32: Цилиндър Metal Work 1100250060CP --> Festo DSNU-25-60-PPV-A | B32: 4 | C32: 4 | D32: 45727 | E32: ACM | F32: 45722.269 | G32: Доставено | H32: 2535091060 | I32: FESTO | J32: 45736 | L32: 45737 | N32: 96.44 | O32: =Cotton_Buds[[#This Row],[Цена за 1 бр. в BGN]]*Cotton_Buds[[#This Row],[Поръчано Количество]] -> 385.76 | R32: {=_xlfn.SWITCH(S32, "ivelikov@septona-bg.com", "Ivan Velikov", "andy@skuytov.eu", "Andrean Angelov", "ialeksandrov@septona-bg.com", "Ivailo Aleksandrov", "bgeorgiev@septona-bg.com", "Boris Georgiev", "iilev@septona-bg.com", "Ivailo Iliev", "dmitev@septona-bg.com", "Dimitar Mitev", "gkanchev@septona-bgc.com", "Georgi Kanchev", "s.kuytov@skuytov.eu", "Salim Kuytov", "istoyanova@septona-bg.com", "Ivelina Stoyanova", "ddimitrova@septona-bg.com", "Doroteya Dimitrova", "smehandzhieva@septona-bg.com", "Stiliana Mehandzhieva", "Unknown" )} -> Unknown
A33: Цилиндър FESTO DSNU-25-55-PPV-A | B33: 1 | C33: 1 | D33: 45736 | E33: ACM | F33: 45722.269 | G33: Доставено | H33: 2535091060 | I33: FESTO | J33: 45736 | L33: 45735 | N33: 111.91 | O33: =Cotton_Buds[[#This Row],[Цена за 1 бр. в BGN]]*Cotton_Buds[[#This Row],[Поръчано Количество]] -> 111.91 | R33: {=_xlfn.SWITCH(S33, "ivelikov@septona-bg.com", "Ivan Velikov", "andy@skuytov.eu", "Andrean Angelov", "ialeksandrov@septona-bg.com", "Ivailo Aleksandrov", "bgeorgiev@septona-bg.com", "Boris Georgiev", "iilev@septona-bg.com", "Ivailo Iliev", "dmitev@septona-bg.com", "Dimitar Mitev", "gkanchev@septona-bgc.com", "Georgi Kanchev", "s.kuytov@skuytov.eu", "Salim Kuytov", "istoyanova@septona-bg.com", "Ivelina Stoyanova", "ddimitrova@septona-bg.com", "Doroteya Dimitrova", "smehandzhieva@septona-bg.com", "Stiliana Mehandzhieva", "Unknown" )} -> Unknown
